
Collecting usage statistics. To deactivate, set browser.gatherUsageStats to false.


  You can now view your Streamlit app in your browser.

  Network URL: http://169.255.255.2:8508
  External URL: http://35.170.135.114:8508

2024-05-03 16:39:12.897 Uncaught app exception
Traceback (most recent call last):
  File "/opt/conda/lib/python3.9/site-packages/streamlit/runtime/scriptrunner/script_runner.py", line 600, in _run_script
    exec(code, module.__dict__)
  File "/home/sagemaker-user/newDEMO/app-kb.py", line 8, in <module>
    sarql=sparqlExecute()
NameError: name 'sparqlExecute' is not defined
2024-05-03 16:40:12.904 Uncaught app exception
Traceback (most recent call last):
  File "/opt/conda/lib/python3.9/site-packages/streamlit/runtime/scriptrunner/script_runner.py", line 600, in _run_script
    exec(code, module.__dict__)
  File "/home/sagemaker-user/newDEMO/app-kb.py", line 7, in <module>
    from sparqlExecute import sparqlExecute
  File "/home/sagemaker-user/newDEMO/sparqlExecute.py", line 28
    """"
        ^
SyntaxError: EOL while scanning string literal
2024-05-03 16:41:08.811 Uncaught app exception
Traceback (most recent call last):
  File "/opt/conda/lib/python3.9/site-packages/streamlit/runtime/scriptrunner/script_runner.py", line 600, in _run_script
    exec(code, module.__dict__)
  File "/home/sagemaker-user/newDEMO/app-kb.py", line 7, in <module>
    from sparqlExecute import sparqlExecution
  File "/home/sagemaker-user/newDEMO/sparqlExecute.py", line 28
    """"
        ^
SyntaxError: EOL while scanning string literal
2024-05-03 16:41:35.724 Uncaught app exception
Traceback (most recent call last):
  File "/opt/conda/lib/python3.9/site-packages/streamlit/runtime/scriptrunner/script_runner.py", line 600, in _run_script
    exec(code, module.__dict__)
  File "/home/sagemaker-user/newDEMO/app-kb.py", line 7, in <module>
    from sparqlExecute import sparqlExecution
  File "/home/sagemaker-user/newDEMO/sparqlExecute.py", line 1, in <module>
    from rdflib import Graph, Namespace
ModuleNotFoundError: No module named 'rdflib'
2024-05-03 16:42:05.259 Uncaught app exception
Traceback (most recent call last):
  File "/opt/conda/lib/python3.9/site-packages/streamlit/runtime/scriptrunner/script_runner.py", line 600, in _run_script
    exec(code, module.__dict__)
  File "/home/sagemaker-user/newDEMO/app-kb.py", line 9, in <module>
    sarql=sparqlExecute()
NameError: name 'sparqlExecute' is not defined
2024-05-03 16:42:22.840 Uncaught app exception
Traceback (most recent call last):
  File "/opt/conda/lib/python3.9/site-packages/streamlit/runtime/scriptrunner/script_runner.py", line 600, in _run_script
    exec(code, module.__dict__)
  File "/home/sagemaker-user/newDEMO/app-kb.py", line 59, in <module>
    st.write(sarql.execute())
TypeError: execute() takes 0 positional arguments but 1 was given
2024-05-03 16:43:05.967 Uncaught app exception
Traceback (most recent call last):
  File "/opt/conda/lib/python3.9/site-packages/streamlit/runtime/scriptrunner/script_runner.py", line 600, in _run_script
    exec(code, module.__dict__)
  File "/home/sagemaker-user/newDEMO/app-kb.py", line 59, in <module>
    st.write(sarql.execute())
  File "/home/sagemaker-user/newDEMO/sparqlExecute.py", line 30, in execute
    qres = g.query(query)
  File "/opt/conda/lib/python3.9/site-packages/rdflib/graph.py", line 1565, in query
    return result(processor.query(query_object, initBindings, initNs, **kwargs))  # type: ignore[arg-type]
  File "/opt/conda/lib/python3.9/site-packages/rdflib/plugins/sparql/processor.py", line 144, in query
    strOrQuery = translateQuery(parseQuery(strOrQuery), base, initNs)
  File "/opt/conda/lib/python3.9/site-packages/rdflib/plugins/sparql/parser.py", line 1542, in parseQuery
    return Query.parseString(q, parseAll=True)
  File "/opt/conda/lib/python3.9/site-packages/pyparsing/util.py", line 256, in _inner
    return fn(self, *args, **kwargs)
  File "/opt/conda/lib/python3.9/site-packages/pyparsing/core.py", line 1200, in parse_string
    raise exc.with_traceback(None)
pyparsing.exceptions.ParseException: Expected SelectQuery, found 'FloodRiskFactor'  (at char 418), (line:13, col:33)
2024-05-03 16:44:46.814 Uncaught app exception
Traceback (most recent call last):
  File "/opt/conda/lib/python3.9/site-packages/streamlit/runtime/scriptrunner/script_runner.py", line 600, in _run_script
    exec(code, module.__dict__)
  File "/home/sagemaker-user/newDEMO/app-kb.py", line 59, in <module>
    st.write(sarql.execute())
  File "/home/sagemaker-user/newDEMO/sparqlExecute.py", line 30, in execute
    qres = g.query(query)
  File "/opt/conda/lib/python3.9/site-packages/rdflib/graph.py", line 1565, in query
    return result(processor.query(query_object, initBindings, initNs, **kwargs))  # type: ignore[arg-type]
  File "/opt/conda/lib/python3.9/site-packages/rdflib/plugins/sparql/processor.py", line 144, in query
    strOrQuery = translateQuery(parseQuery(strOrQuery), base, initNs)
  File "/opt/conda/lib/python3.9/site-packages/rdflib/plugins/sparql/parser.py", line 1542, in parseQuery
    return Query.parseString(q, parseAll=True)
  File "/opt/conda/lib/python3.9/site-packages/pyparsing/util.py", line 256, in _inner
    return fn(self, *args, **kwargs)
  File "/opt/conda/lib/python3.9/site-packages/pyparsing/core.py", line 1200, in parse_string
    raise exc.with_traceback(None)
pyparsing.exceptions.ParseException: Expected SelectQuery, found 'FloodRiskFactor'  (at char 427), (line:13, col:33)
2024-05-03 16:45:05.217 Uncaught app exception
Traceback (most recent call last):
  File "/opt/conda/lib/python3.9/site-packages/streamlit/runtime/scriptrunner/script_runner.py", line 600, in _run_script
    exec(code, module.__dict__)
  File "/home/sagemaker-user/newDEMO/app-kb.py", line 59, in <module>
    st.write(sarql.execute())
  File "/home/sagemaker-user/newDEMO/sparqlExecute.py", line 30, in execute
    qres = g.query(query)
  File "/opt/conda/lib/python3.9/site-packages/rdflib/graph.py", line 1565, in query
    return result(processor.query(query_object, initBindings, initNs, **kwargs))  # type: ignore[arg-type]
  File "/opt/conda/lib/python3.9/site-packages/rdflib/plugins/sparql/processor.py", line 144, in query
    strOrQuery = translateQuery(parseQuery(strOrQuery), base, initNs)
  File "/opt/conda/lib/python3.9/site-packages/rdflib/plugins/sparql/parser.py", line 1542, in parseQuery
    return Query.parseString(q, parseAll=True)
  File "/opt/conda/lib/python3.9/site-packages/pyparsing/util.py", line 256, in _inner
    return fn(self, *args, **kwargs)
  File "/opt/conda/lib/python3.9/site-packages/pyparsing/core.py", line 1200, in parse_string
    raise exc.with_traceback(None)
pyparsing.exceptions.ParseException: Expected SelectQuery, found 'FloodRiskFactor'  (at char 427), (line:13, col:33)
2024-05-03 16:45:31.444 Uncaught app exception
Traceback (most recent call last):
  File "/opt/conda/lib/python3.9/site-packages/streamlit/runtime/scriptrunner/script_runner.py", line 600, in _run_script
    exec(code, module.__dict__)
  File "/home/sagemaker-user/newDEMO/app-kb.py", line 59, in <module>
    st.write(sarql.execute())
  File "/home/sagemaker-user/newDEMO/sparqlExecute.py", line 30, in execute
    qres = g.query(query)
  File "/opt/conda/lib/python3.9/site-packages/rdflib/graph.py", line 1565, in query
    return result(processor.query(query_object, initBindings, initNs, **kwargs))  # type: ignore[arg-type]
  File "/opt/conda/lib/python3.9/site-packages/rdflib/plugins/sparql/processor.py", line 144, in query
    strOrQuery = translateQuery(parseQuery(strOrQuery), base, initNs)
  File "/opt/conda/lib/python3.9/site-packages/rdflib/plugins/sparql/parser.py", line 1542, in parseQuery
    return Query.parseString(q, parseAll=True)
  File "/opt/conda/lib/python3.9/site-packages/pyparsing/util.py", line 256, in _inner
    return fn(self, *args, **kwargs)
  File "/opt/conda/lib/python3.9/site-packages/pyparsing/core.py", line 1200, in parse_string
    raise exc.with_traceback(None)
pyparsing.exceptions.ParseException: Expected SelectQuery, found 'FloodRiskFactor'  (at char 418), (line:13, col:33)
2024-05-03 16:46:34.089 Uncaught app exception
Traceback (most recent call last):
  File "/opt/conda/lib/python3.9/site-packages/streamlit/runtime/scriptrunner/script_runner.py", line 600, in _run_script
    exec(code, module.__dict__)
  File "/home/sagemaker-user/newDEMO/app-kb.py", line 59, in <module>
    st.write(sarql.execute())
  File "/home/sagemaker-user/newDEMO/sparqlExecute.py", line 30, in execute
    qres = g.query(query)
  File "/opt/conda/lib/python3.9/site-packages/rdflib/graph.py", line 1565, in query
    return result(processor.query(query_object, initBindings, initNs, **kwargs))  # type: ignore[arg-type]
  File "/opt/conda/lib/python3.9/site-packages/rdflib/plugins/sparql/processor.py", line 144, in query
    strOrQuery = translateQuery(parseQuery(strOrQuery), base, initNs)
  File "/opt/conda/lib/python3.9/site-packages/rdflib/plugins/sparql/parser.py", line 1542, in parseQuery
    return Query.parseString(q, parseAll=True)
  File "/opt/conda/lib/python3.9/site-packages/pyparsing/util.py", line 256, in _inner
    return fn(self, *args, **kwargs)
  File "/opt/conda/lib/python3.9/site-packages/pyparsing/core.py", line 1200, in parse_string
    raise exc.with_traceback(None)
pyparsing.exceptions.ParseException: Expected SelectQuery, found 'FloodRiskFactor'  (at char 418), (line:13, col:33)
2024-05-03 16:48:12.412 Uncaught app exception
Traceback (most recent call last):
  File "/opt/conda/lib/python3.9/site-packages/streamlit/runtime/scriptrunner/script_runner.py", line 600, in _run_script
    exec(code, module.__dict__)
  File "/home/sagemaker-user/newDEMO/app-kb.py", line 59, in <module>
    st.write(sarql.execute())
  File "/home/sagemaker-user/newDEMO/sparqlExecute.py", line 36, in execute
    qres = g.query(query)
  File "/opt/conda/lib/python3.9/site-packages/rdflib/graph.py", line 1565, in query
    return result(processor.query(query_object, initBindings, initNs, **kwargs))  # type: ignore[arg-type]
  File "/opt/conda/lib/python3.9/site-packages/rdflib/plugins/sparql/processor.py", line 144, in query
    strOrQuery = translateQuery(parseQuery(strOrQuery), base, initNs)
  File "/opt/conda/lib/python3.9/site-packages/rdflib/plugins/sparql/parser.py", line 1542, in parseQuery
    return Query.parseString(q, parseAll=True)
  File "/opt/conda/lib/python3.9/site-packages/pyparsing/util.py", line 256, in _inner
    return fn(self, *args, **kwargs)
  File "/opt/conda/lib/python3.9/site-packages/pyparsing/core.py", line 1200, in parse_string
    raise exc.with_traceback(None)
pyparsing.exceptions.ParseException: Expected SelectQuery, found '?'  (at char 75), (line:4, col:17)
2024-05-03 16:49:46.179 Uncaught app exception
Traceback (most recent call last):
  File "/opt/conda/lib/python3.9/site-packages/streamlit/runtime/scriptrunner/script_runner.py", line 600, in _run_script
    exec(code, module.__dict__)
  File "/home/sagemaker-user/newDEMO/app-kb.py", line 7, in <module>
    from sparqlExecute import sparqlExecution
  File "/home/sagemaker-user/newDEMO/sparqlExecute.py", line 41
    for row in qres:
IndentationError: unexpected indent
2024-05-03 16:50:10.437 Uncaught app exception
Traceback (most recent call last):
  File "/opt/conda/lib/python3.9/site-packages/streamlit/runtime/scriptrunner/script_runner.py", line 600, in _run_script
    exec(code, module.__dict__)
  File "/home/sagemaker-user/newDEMO/app-kb.py", line 59, in <module>
    st.write(sarql.execute())
  File "/home/sagemaker-user/newDEMO/sparqlExecute.py", line 36, in execute
    qres = g.query(query)
  File "/opt/conda/lib/python3.9/site-packages/rdflib/graph.py", line 1565, in query
    return result(processor.query(query_object, initBindings, initNs, **kwargs))  # type: ignore[arg-type]
  File "/opt/conda/lib/python3.9/site-packages/rdflib/plugins/sparql/processor.py", line 144, in query
    strOrQuery = translateQuery(parseQuery(strOrQuery), base, initNs)
  File "/opt/conda/lib/python3.9/site-packages/rdflib/plugins/sparql/parser.py", line 1542, in parseQuery
    return Query.parseString(q, parseAll=True)
  File "/opt/conda/lib/python3.9/site-packages/pyparsing/util.py", line 256, in _inner
    return fn(self, *args, **kwargs)
  File "/opt/conda/lib/python3.9/site-packages/pyparsing/core.py", line 1200, in parse_string
    raise exc.with_traceback(None)
pyparsing.exceptions.ParseException: Expected SelectQuery, found '?'  (at char 75), (line:4, col:17)
2024-05-03 16:50:42.885 Uncaught app exception
Traceback (most recent call last):
  File "/opt/conda/lib/python3.9/site-packages/streamlit/runtime/scriptrunner/script_runner.py", line 600, in _run_script
    exec(code, module.__dict__)
  File "/home/sagemaker-user/newDEMO/app-kb.py", line 59, in <module>
    st.write(sarql.execute())
  File "/home/sagemaker-user/newDEMO/sparqlExecute.py", line 36, in execute
    qres = g.query(query)
  File "/opt/conda/lib/python3.9/site-packages/rdflib/graph.py", line 1565, in query
    return result(processor.query(query_object, initBindings, initNs, **kwargs))  # type: ignore[arg-type]
  File "/opt/conda/lib/python3.9/site-packages/rdflib/plugins/sparql/processor.py", line 144, in query
    strOrQuery = translateQuery(parseQuery(strOrQuery), base, initNs)
  File "/opt/conda/lib/python3.9/site-packages/rdflib/plugins/sparql/parser.py", line 1542, in parseQuery
    return Query.parseString(q, parseAll=True)
  File "/opt/conda/lib/python3.9/site-packages/pyparsing/util.py", line 256, in _inner
    return fn(self, *args, **kwargs)
  File "/opt/conda/lib/python3.9/site-packages/pyparsing/core.py", line 1200, in parse_string
    raise exc.with_traceback(None)
pyparsing.exceptions.ParseException: Expected SelectQuery, found '?'  (at char 75), (line:4, col:17)
2024-05-03 17:03:18.371 Uncaught app exception
Traceback (most recent call last):
  File "/opt/conda/lib/python3.9/site-packages/streamlit/runtime/scriptrunner/script_runner.py", line 600, in _run_script
    exec(code, module.__dict__)
  File "/home/sagemaker-user/newDEMO/app-kb.py", line 59, in <module>
    st.write(sarql.execute())
  File "/home/sagemaker-user/newDEMO/sparqlExecute.py", line 36, in execute
    qres = g.query(query)
  File "/opt/conda/lib/python3.9/site-packages/rdflib/graph.py", line 1565, in query
    return result(processor.query(query_object, initBindings, initNs, **kwargs))  # type: ignore[arg-type]
  File "/opt/conda/lib/python3.9/site-packages/rdflib/plugins/sparql/processor.py", line 144, in query
    strOrQuery = translateQuery(parseQuery(strOrQuery), base, initNs)
  File "/opt/conda/lib/python3.9/site-packages/rdflib/plugins/sparql/parser.py", line 1542, in parseQuery
    return Query.parseString(q, parseAll=True)
  File "/opt/conda/lib/python3.9/site-packages/pyparsing/util.py", line 256, in _inner
    return fn(self, *args, **kwargs)
  File "/opt/conda/lib/python3.9/site-packages/pyparsing/core.py", line 1200, in parse_string
    raise exc.with_traceback(None)
pyparsing.exceptions.ParseException: Expected SelectQuery, found '?'  (at char 75), (line:4, col:17)
2024-05-03 17:05:05.271 Uncaught app exception
Traceback (most recent call last):
  File "/opt/conda/lib/python3.9/site-packages/streamlit/runtime/scriptrunner/script_runner.py", line 600, in _run_script
    exec(code, module.__dict__)
  File "/home/sagemaker-user/newDEMO/app-kb.py", line 59, in <module>
    st.write(sarql.execute())
  File "/home/sagemaker-user/newDEMO/sparqlExecute.py", line 37, in execute
    qres = g.query(query)
  File "/opt/conda/lib/python3.9/site-packages/rdflib/graph.py", line 1565, in query
    return result(processor.query(query_object, initBindings, initNs, **kwargs))  # type: ignore[arg-type]
  File "/opt/conda/lib/python3.9/site-packages/rdflib/plugins/sparql/processor.py", line 144, in query
    strOrQuery = translateQuery(parseQuery(strOrQuery), base, initNs)
  File "/opt/conda/lib/python3.9/site-packages/rdflib/plugins/sparql/parser.py", line 1542, in parseQuery
    return Query.parseString(q, parseAll=True)
  File "/opt/conda/lib/python3.9/site-packages/pyparsing/util.py", line 256, in _inner
    return fn(self, *args, **kwargs)
  File "/opt/conda/lib/python3.9/site-packages/pyparsing/core.py", line 1200, in parse_string
    raise exc.with_traceback(None)
pyparsing.exceptions.ParseException: Expected SelectQuery, found ':'  (at char 75), (line:4, col:17)
2024-05-03 17:05:38.184 Uncaught app exception
Traceback (most recent call last):
  File "/opt/conda/lib/python3.9/site-packages/streamlit/runtime/scriptrunner/script_runner.py", line 600, in _run_script
    exec(code, module.__dict__)
  File "/home/sagemaker-user/newDEMO/app-kb.py", line 59, in <module>
    st.write(sarql.execute())
  File "/home/sagemaker-user/newDEMO/sparqlExecute.py", line 37, in execute
    qres = g.query(query)
  File "/opt/conda/lib/python3.9/site-packages/rdflib/graph.py", line 1565, in query
    return result(processor.query(query_object, initBindings, initNs, **kwargs))  # type: ignore[arg-type]
  File "/opt/conda/lib/python3.9/site-packages/rdflib/plugins/sparql/processor.py", line 144, in query
    strOrQuery = translateQuery(parseQuery(strOrQuery), base, initNs)
  File "/opt/conda/lib/python3.9/site-packages/rdflib/plugins/sparql/parser.py", line 1542, in parseQuery
    return Query.parseString(q, parseAll=True)
  File "/opt/conda/lib/python3.9/site-packages/pyparsing/util.py", line 256, in _inner
    return fn(self, *args, **kwargs)
  File "/opt/conda/lib/python3.9/site-packages/pyparsing/core.py", line 1200, in parse_string
    raise exc.with_traceback(None)
pyparsing.exceptions.ParseException: Expected SelectQuery, found ':'  (at char 75), (line:4, col:17)
2024-05-03 17:06:41.254 Uncaught app exception
Traceback (most recent call last):
  File "/opt/conda/lib/python3.9/site-packages/streamlit/runtime/scriptrunner/script_runner.py", line 600, in _run_script
    exec(code, module.__dict__)
  File "/home/sagemaker-user/newDEMO/app-kb.py", line 59, in <module>
    st.write(sarql.execute())
  File "/home/sagemaker-user/newDEMO/sparqlExecute.py", line 37, in execute
    qres = g.query(query)
  File "/opt/conda/lib/python3.9/site-packages/rdflib/graph.py", line 1565, in query
    return result(processor.query(query_object, initBindings, initNs, **kwargs))  # type: ignore[arg-type]
  File "/opt/conda/lib/python3.9/site-packages/rdflib/plugins/sparql/processor.py", line 144, in query
    strOrQuery = translateQuery(parseQuery(strOrQuery), base, initNs)
  File "/opt/conda/lib/python3.9/site-packages/rdflib/plugins/sparql/parser.py", line 1542, in parseQuery
    return Query.parseString(q, parseAll=True)
  File "/opt/conda/lib/python3.9/site-packages/pyparsing/util.py", line 256, in _inner
    return fn(self, *args, **kwargs)
  File "/opt/conda/lib/python3.9/site-packages/pyparsing/core.py", line 1200, in parse_string
    raise exc.with_traceback(None)
pyparsing.exceptions.ParseException: Expected SelectQuery, found 'FloodResponse'  (at char 75), (line:4, col:17)
2024-05-03 17:10:42.213 Uncaught app exception
Traceback (most recent call last):
  File "/opt/conda/lib/python3.9/site-packages/streamlit/runtime/scriptrunner/script_runner.py", line 600, in _run_script
    exec(code, module.__dict__)
  File "/home/sagemaker-user/newDEMO/app-kb.py", line 7, in <module>
    from sparqlExecute import sparqlExecution
  File "/home/sagemaker-user/newDEMO/sparqlExecute.py", line 15
    PREFIX owl: <http://www.w3.org/2002/07/owl#>
           ^
SyntaxError: invalid syntax
2024-05-03 17:12:25.019 Uncaught app exception
Traceback (most recent call last):
  File "/opt/conda/lib/python3.9/site-packages/streamlit/runtime/scriptrunner/script_runner.py", line 600, in _run_script
    exec(code, module.__dict__)
  File "/home/sagemaker-user/newDEMO/app-kb.py", line 7, in <module>
    from sparqlExecute import sparqlExecution
  File "/home/sagemaker-user/newDEMO/sparqlExecute.py", line 46
    st.write(f"Property: {row.property})
                                        ^
SyntaxError: EOL while scanning string literal
